<?xml version="1.0" encoding="UTF-8"?>
<testsuite name="test_request_vaccine_tests.MyTestCase-20220309224116" tests="1" file="test_request_vaccine_tests.py" time="0.006" timestamp="2022-03-09T22:41:16" failures="1" errors="0" skipped="0">
	<testcase classname="test_request_vaccine_tests.MyTestCase" name="test_something" time="0.006" timestamp="2022-03-09T22:41:16">
		<failure type="AssertionError" message="True != False"><![CDATA[Traceback (most recent call last):
  File "/Library/Frameworks/Python.framework/Versions/3.8/lib/python3.8/unittest/case.py", line 60, in testPartExecutor
    yield
  File "/Library/Frameworks/Python.framework/Versions/3.8/lib/python3.8/unittest/case.py", line 676, in run
    self._callTestMethod(testMethod)
  File "/Library/Frameworks/Python.framework/Versions/3.8/lib/python3.8/unittest/case.py", line 633, in _callTestMethod
    method()
  File "/Users/lorenzo/PycharmProjects/G50.2022.T11.EG3/src/unittest/python/test_request_vaccine_tests.py", line 6, in test_something
    self.assertEqual(True, False)
  File "/Library/Frameworks/Python.framework/Versions/3.8/lib/python3.8/unittest/case.py", line 912, in assertEqual
    assertion_func(first, second, msg=msg)
  File "/Library/Frameworks/Python.framework/Versions/3.8/lib/python3.8/unittest/case.py", line 905, in _baseAssertEqual
    raise self.failureException(msg)
AssertionError: True != False
]]></failure>
	</testcase>
</testsuite>
